Workbook
Name AICPA: #REF!
Name AICPA: #REF!
Name Automated: #REF!
Name Automated: #REF!
Name CBInspection10a: 'Control Activity-1 - v2016'!$A$57
Name CBInspection10a: 'Control Activity-2 - v2016'!$A$57
Name CBInspection10a: 'Master Control Activity v2016'!$A$57
Name CBInspection10b: 'Control Activity-1 - v2016'!$H$57
Name CBInspection10b: 'Control Activity-2 - v2016'!$H$57
Name CBInspection10b: 'Master Control Activity v2016'!$H$57
Name CBInspection20a: 'Control Activity-1 - v2016'!$A$58
Name CBInspection20a: 'Control Activity-2 - v2016'!$A$58
Name CBInspection20a: 'Master Control Activity v2016'!$A$58
Name CBInspection20b: 'Control Activity-1 - v2016'!$H$58
Name CBInspection20b: 'Control Activity-2 - v2016'!$H$58
Name CBInspection20b: 'Master Control Activity v2016'!$H$58
Name CBInspection30a: 'Control Activity-1 - v2016'!$A$59
Name CBInspection30a: 'Control Activity-2 - v2016'!$A$59
Name CBInspection30a: 'Master Control Activity v2016'!$A$59
Name CBInspection30b: 'Control Activity-1 - v2016'!$H$59
Name CBInspection30b: 'Control Activity-2 - v2016'!$H$59
Name CBInspection30b: 'Master Control Activity v2016'!$H$59
Name CBInspection40a: 'Control Activity-1 - v2016'!$A$60
Name CBInspection40a: 'Control Activity-2 - v2016'!$A$60
Name CBInspection40a: 'Master Control Activity v2016'!$A$60
Name CBInspection40b: 'Control Activity-1 - v2016'!$H$60
Name CBInspection40b: 'Control Activity-2 - v2016'!$H$60
Name CBInspection40b: 'Master Control Activity v2016'!$H$60
Name CBInspection50a: 'Control Activity-1 - v2016'!$A$61
Name CBInspection50a: 'Control Activity-2 - v2016'!$A$61
Name CBInspection50a: 'Master Control Activity v2016'!$A$61
Name CBInspection50b: 'Control Activity-1 - v2016'!$H$61
Name CBInspection50b: 'Control Activity-2 - v2016'!$H$61
Name CBInspection50b: 'Master Control Activity v2016'!$H$61
Name CBInspection60a: 'Control Activity-1 - v2016'!$A$62
Name CBInspection60a: 'Control Activity-2 - v2016'!$A$62
Name CBInspection60a: 'Master Control Activity v2016'!$A$62
Name CBInspection60b: 'Control Activity-1 - v2016'!$H$62
Name CBInspection60b: 'Control Activity-2 - v2016'!$H$62
Name CBInspection60b: 'Master Control Activity v2016'!$H$62
Name CBInspection70a: 'Control Activity-1 - v2016'!$A$63
Name CBInspection70a: 'Control Activity-2 - v2016'!$A$63
Name CBInspection70a: 'Master Control Activity v2016'!$A$63
Name CBInspection70b: 'Control Activity-1 - v2016'!$H$63
Name CBInspection70b: 'Control Activity-2 - v2016'!$H$63
Name CBInspection70b: 'Master Control Activity v2016'!$H$63
Name ControlDesignStarter: 'Master Control Design'!$A$11
Name ControlType: #REF!
Name ControlType: #REF!
Name Debug: 'Drop down'!$C$16
Name DesignEvaluationRow: DataSheet!$B$14:$R$14
Name DesiredEvidence: 'Drop down'!$I$6:$I$9
Name DesiredEvidence: 'Drop down'!$I$6:$I$9
Name DoNotUncheckBoxes123456: 'Control Activity-1 - v2016'!$A$2
Name DoNotUncheckBoxes123456: 'Control Activity-2 - v2016'!$A$2
Name DoNotUncheckBoxes123456: 'Master Control Activity v2016'!$A$2
Name DoNotUncheckBoxes123456: 'Master Control Design'!$A$2
Name DoNotUncheckBoxes123456: 'Master Procedures (1)'!$A$2
Name DoNotUncheckBoxes123456: 'Master Procedures (10)'!$A$2
Name DoNotUncheckBoxes123456: 'Master Procedures (11)'!$A$2

Sheet Master Procedures (51)
B1: Prior year control testing documentation rolled forward for reference purposes.
B2: Perform testing using inquiry, observation, inspection and reperformance
B3: When more than one preparer was involved in the completion of this EGA, document the names of the team members involved and the procedures performed. | G3: [Document the initials or names of team members and procedures performed (e.g., Jane Doe performed step a) below)]
B6: Intrusion prevention/detection and monitoring (PCAOB engagements)
B7: Procedures | G7: Results | L7: Links
B8: a) | C8: Verify whether there have been changes to the design of the control. | H8: Verified whether there have been changes to the design of the control, and
I9: No changes were noted in the design of the control, or
I10: Changes were noted in the design of the control.
H11: [Document procedures performed and changes, as necessary]
B13: b) | C13: Inquiry Inquire of personnel knowledgeable of the control to test the various aspects of the control. | H13: Not applicable. Additional inquiry not performed. | N13: TRUE
G14: OR
H15: Inquired and documented in a related EGA addressing the understanding and evaluation of entity's ITGCs or in a related EGA addressing the understanding and evaluation of entity's internal control.
C17: Note: One Cyber resources are available to assist US engagement teams with the completion of this EGA. For non-US teams consider engaging similar specialist support available in your territory.
H18: [provide link]
G20: OR
H21: Inquired of personnel knowledgeable of the control considering the various aspects of the control (including any automated control components):
H23: - | I23: Policies and/or procedures related to the entity's security incident monitoring program.
I24: - | J24: Whether an in-house group (e.g., Security Operation Center) is used to manage the security incident management program, or whether the program (or aspects thereof) are outsourced to a third party service organization (i.e. Managed Security Service Provider).
I27: - | J27: The mechanisms used by the entity to monitor its security incident monitoring program, such as a dedicated tool, or through an embedded security function (e.g. next generation firewall system).
I30: - | J30: How management ensures that all networks and technology assets related to financially significant systems are considered in the security incident monitoring program.
H32: - | I32: An understanding of how the entity has architected its network, including:
I33: - | J33: How the entity segments its network across all systems and areas of operation, as well as how access between network segments (i.e., between Virtual Local Area Networks or “VLANs”) are restricted.
I36: - | J36: How the entity protects its network through firewalls, demilitarized zones (“DMZs”) and other security incident protection measures.
J39: A demilitarized zone or "DMZ" is a segment of a Company's network carved off and isolated from the rest of its network. A firewall is used to restrict and monitor traffic between the DMZ and trusted and untrusted sources that the DMZ is exposed to, such as a separate DMZ or the internet. A Company may choose to use a combination of DMZs and firewalls to protect its IT environment
H45: - | I45: Whether logs are configured to identify potential security incidents, and
I46: - | J46: Whether an alerting mechanism is in place to notify relevant personnel of potential security incidents.
I48: - | J48: Whether access to the logs is restricted to appropriate personnel.
I49: - | J49: How the logs are analyzed to identify potential security incidents warranting further investigation.
I51: - | J51: Whether the logs are complete and inclusive of all potential security incidents identified in the environment.
H53: - | I53: Whether a process is in place to assess, risk categorize and address identified security incidents.
H54: - | I54: How the security incident monitoring program is used to assess, risk categorize and address identified security incidents.
I56: - | J56: The framework and criteria used by the entity to assess and risk categorize identified security incidents.
I58: - | J58: Whether a root cause analysis is performed for identified security incidents.
I59: - | J59: Whether defined service level objectives are in place for addressing identified security incidents based on risk categorization.
I61: - | J61: How evidence of investigation and remediation of identified security incidents is retained (e.g. a dedicated case management system).
I63: - | J63: How relevant stakeholders are made aware of security incidents.
I64: - | J64: Whether documented playbooks are in place for addressing common or frequently identified security incidents.
I66: - | J66: Whether there is a documented incident response plan and whether the incident plan is periodically tested.
H68: - | I68: Whether periodic network penetration tests are performed.
I69: - | J69: How frequently the tests are performed.
...

Sheet Master Procedures (52)
B1: Prior year control testing documentation rolled forward for reference purposes.
B2: Perform testing using inquiry, observation, inspection and reperformance
B3: When more than one preparer was involved in the completion of this EGA, document the names of the team members involved and the procedures performed. | G3: [Document the initials or names of team members and procedures performed (e.g., Jane Doe performed step a) below)]
B6: Patch management (PCAOB engagements)
B7: Procedures | G7: Results | L7: Links
B8: a) | C8: Verify whether there have been changes to the design of the control. | H8: Verified whether there have been changes to the design of the control, and
I9: No changes were noted in the design of the control, or
I10: Changes were noted in the design of the control.
H11: [Document procedures performed and changes, as necessary]
B13: b) | C13: Inquiry Inquire of personnel knowledgeable of the control to test the various aspects of the control. | H13: Not applicable. Additional inquiry not performed. | N13: TRUE
G14: OR
H15: Inquired and documented in a related EGA addressing the understanding and evaluation of entity's ITGCs or in a related EGA addressing the understanding and evaluation of entity's internal control.
H18: [provide link]
G19: OR
H20: Inquired of personnel knowledgeable of the control considering the various aspects of the control (including any automated control components):
C21: Note: An organization may structure their patch management process as a component of the overall vulnerability management program. Therefore, in gaining an understanding of an organization's policies and/or procedures related to patch management, it may be necessary to gain a broader understanding of the organization's vulnerability management program, including the policies and/or procedures related to how vulnerabilities are identified, evaluated, and addressed.
H22: - | I22: Obtain an understanding of the entity's patch management program including:
I23: - | J23: Policies and/or procedures related to the entity's patch management program.
I24: - | J24: How the entity is notified of patches by external vendors (e.g., Microsoft for Windows patches).
I26: - | J26: Whether patches are installed automatically or manually, and whether a defined schedule is used to install patches for various technologies, including network devices (e.g., firewalls and virtual private networks), operating systems, applications, and databases.
I29: - | J29: Whether a tool is used to monitor for and deploy patches.
I30: - | J30: Whether documented service level objectives are defined based on the inherent nature of a missing/unapplied patch and/or the type of technology asset (e.g., the service level objective for an internet-facing technology asset may vary from the service level objective for an asset that is not exposed to the internet).
I34: - | J34: The process by which patches are tested prior to being deployed to the production environment.
I36: - | J36: Whether there is a separately defined process for emergency or high priority patches.
I37: - | J37: How management ensures that all technologies, including network devices (e.g., firewalls and virtual private networks), operating systems, applications, and databases, are considered in the patch management program.
I40: - | J40: Whether the services of third parties are used in the entity's patch management program, including responsibilities for patching of externally hosted applications or software used in a Software as a Service (“SaaS”) model.
I43: - | J43: Whether separate patch management processes are in place for different technology platforms (e.g., Windows vs. Unix platforms).
H45: - | I45: How appropriate personnel are periodically informed of the status of the patch management program, including the adoption and effectiveness of patches across the environment.
I47: - | J47: The mechanism and frequency of notification (e.g., quarterly risk committee meetings).
I48: - | J48: The level of detail provided (e.g., metrics related to patch adoption and effectiveness).
I49: - | J49: Whether appropriate personnel (e.g., CIO, CTO, CISO, operational risk, technology risk) are informed of the status of patch management program.
H51: - | I51: How management addresses vulnerabilities attributable to missed/unapplied patches.
I52: - | J52: Whether periodic scans are performed to identify potential vulnerabilities attributable to missed/unapplied security patches.
I54: - | J54: Whether an exemption or risk acceptance process is in place for patches that cannot be deployed due to system limitations and/or business constraints.
H56: - | I56: The period for which the control has been in operation and the frequency of its operation.
H57: - | I57: The appropriateness of the person(s) performing the control(s).
H59: [document the various aspects of the control considered]
H60: [document details, name and date of inquiry]
B62: c) | C62: Observation During the normal course of processing, observe the control operator performing the control. | H62: Not applicable. Observation not performed. | N62: TRUE
G63: OR
...

Sheet Master Procedures (53)
B1: Prior year control testing documentation rolled forward for reference purposes.
B2: Perform testing using inquiry, observation and inspection
B3: When more than one preparer was involved in the completion of this EGA, document the names of the team members involved and the procedures performed. | G3: [Document the initials or names of team members and procedures performed (e.g., Jane Doe performed step a) below)]
B6: Comp. operations - Data is appropriately backed up and recoverable (PCAOB engagements)
B7: Procedures | G7: Results | L7: Links
B8: a) | C8: Inquiry | H8: Not applicable. Additional Inquiry not performed. | N8: TRUE
C9: Inquire of personnel knowledgeable of the control (including any automated components) to test the various aspects of the control. | G9: OR
H10: Inquired and documented in a related EGA addressing the understanding and evaluation of entity's ITGCs or in a related EGA addressing the understanding and evaluation of entity's internal control.
C13: Note: Consider the entity's ability to backup and recover systems and/or data to report its quarterly (if applicable) and annual financials in a timely manner. | H13: [provide link]
G14: OR
H15: Inquired of personnel knowledgeable of the control considering the various aspects of the control (including any automated control components):
H17: - | I17: Policies and/or procedures related to the entities backup and recovery process(es).
H18: - | I18: Whether third parties are used to perform services related to backup and recovery (e.g., cloud providers).
H20: - | I20: How the control operator determines which types of data are included and the frequency of the backup cycle.
H22: - | I22: How changes to the backup configuration(s) and/or schedule(s) are managed.
H23: - | I23: How the control operator monitors backups for successful completion.
H24: - | I24: How the control operator resolves errors encountered during the backup process(es).
H25: - | I25: How the control operator ensures that backup media would be available in the event of an emergency (e.g., off-site rotation of media, replication of data to hot/cold site, cloud, etc.).
H27: - | I27: Whether data is stored on premise, off premise, direct-to-cloud, etc.
H28: - | I28: Has management established a recovery time objective (RTO) (i.e., amount of time allotted for the recovery of a business function or resource after an incident occurs) for financially significant applications and related infrastructure.
H31: - | I31: Has management established a recovery point objective (RPO) (i.e., amount of the data that can be lost before a material impact to financial reporting occurs) for financially significant applications and related infrastructure.
H34: - | I34: How the system has been configured to back up financially significant data on a scheduled (e.g., partial, incremental, full backups) or real-time basis.
H36: - | I36: How the control operator periodically tests backups for recoverability against the entity's defined RTO and RPO (e.g., scheduled testing, throughout the period when recovering from processing problems, etc.).
... H44: - | I44: The appropriateness of the person(s) performing the control(s).
H46: [document the various aspects of the control considered]
H47: [document details, name and date of inquiry]
B49: b) | C49: Observation During the normal course of processing, observe the control operator performing the control in accordance with agreed upon policies and/or procedures, including any considerations for automated components in the process. | H49: Not applicable. Observation not performed. | N49: TRUE
G50: OR
H51: Observed and documented in a related EGA addressing the understanding and evaluation of entity's ITGCs or in a related EGA addressing the understanding and evaluation of entity's internal control.
H54: [provide link]
G55: OR
H56: Observed the control operator performing the control, may include the following:
H57: - | I57: Initiating a backup, and
H58: - | I58: Monitoring backup for successful completion, and
H59: - | I59: Resolving errors encountered during backup, and
H60: - | I60: Recovering from a backup, and
H61: - | I61: Following up on exceptions noted during testing of backup and recoverability
H62: [document details of observation, name and date of observation]
B64: c) | C64: Inspection Inspect the following: | H64: Not applicable. Inspection not performed. | N64: TRUE
G65: OR
...

Sheet Master Control Design
B1: Prior year control testing documentation rolled forward for reference purposes.
B2: Review 통제 - 설계 평가 Review control - design evaluation
B3: Note: 동 template은 감사팀의 review control 설계에 대한 평가를 문서화하는 업무흐름도(해당하는 경우) 및 "추적조사" template을 보완하기 위한 목적임. Note: This template is meant to complement a flowchart (if applicable) and “walkthrough” template for documenting our evaluation of the design of review controls.
B4: 통제 번호 Control number
B5: 통제/프로그램의 내용 Description of the control/program
B6: 평가대상 통제의 대상 부문 Component(s) of the entity covered by the control being evaluated
B7: 통제 대상이 되는 부문의 계정(또는, 재무제표 전반) Account(s) at the component(s) covered by the control, or pervasive | H7: 설계의 효과성 및 실행 여부에 대한 평가 Evaluation of design effectiveness and implementation | N7: 정보의 질 Quality of Information | R7: 설계 효과성에 대한 결론 Conclusion of design effectiveness
B8: 세부 통제 활동 # Detailed Control Activity # | C8: 해당 통제 활동과 관련있는 잠재적 왜곡표시의 가능한 원천('LSPM')은 무엇인가? (Aura 내 "Risk Strategy" view에서 복사하여 붙여넣기) Which LSPM(s) is relevant for this control activity (copy and paste from the "Risk Strategy" view within Aura)? | D8: 해당 통제 활동의 목적은 무엇인가? (즉, 통제 운영자가 동 통제 활동을 통해 달성하고자 하는 것이 무엇인가) What is the objective of the control activity (i.e., what is the control operator expected to accomplish for this control activity)? | E8: 질문 일자 및 질문 대상자를 문서화 (다른 곳에서 이미 문서화하지 않은 경우) Document date of inquiry, with whom discussed if not already documented. | F8: 통제 활동 운영자 Control activity operator | G8: 통제 운영자가 효과적으로 통제를 수행하기 위해 필요한 권한 및 능력을 갖추고 있는가? Does the control operator possess the necessary authority and competence to perform the control effectively? | H8: 통제 운영자가 통제 활동의 목적을 어떻게 달성하는가? How does the control operator accomplish the objective of this control activity? | N8: (해당사항이 있는 경우)이 통제 활동의 효과적인 운영에 중요하게 사용되는 정보(예, key report)에 대한 설명 Describe the information (e.g., key report) determined to be used in and important to the effective execution of this control activity, if any | O8: 이러한 정보의 원천 Describe the source of this information | P8: 이 통제 활동의 운영에 중요하게 사용되는 정보의 신뢰성(즉, 완전성 및 정확성)에 대한 확신을 얻기 위하여, 경영진이 의존하는 통제 또는 통제 활동의 내용 For information determined to be used in and important to the operation of this control activity, describe the control or control activities management is relying on to provide assurance regarding the reliability (i.e., it is complete and accurate) of such information. | Q8: Review control이 추정의 합리성에 대한 평가와 관련된 경우, 관련된 유의적 가정을 뒷받침하는 충분한 세부내역이 통제 운영자에게 제공되는지 설명. 그렇지 않다면, 어떻게 충분히 정확한 검토가 달성되는지 설명. If the review involves an assessment of the reasonableness of an estimate, describe whether the control operator is provided with sufficient details in support of underlying significant assumptions. If not, describe how a sufficiently precise review is achieved. | R8: 통제 활동이 명시된 목적을 달성할 수 있도록 효과적으로 설계되었는가? 그렇지 않다면, 근거, SAD에 대한 참조번호 및 감사 계획에 미치는 영향을 문서화. Describe whether the control activity is designed effectively to meet the stated objective. If "No", document rationale, reference to the SAD and impact to audit plan.
H9: 각 통제 활동 내에서 통제 운영자가 정확하게 무엇을 수행하는지 세부적으로 기재. Describe in detail what exactly the control operator does in performing each control activity. | I9: 정밀함의 수준? At what level of precision? | M9: 통제 운영자가 실제로 통제 활동을 수행하였음을 입증하는, 입수된 감사증거(관련 문서 포함)의 성격 및 형태 Describe the nature and form of evidence, including documentation, obtained that demonstrates the control operator actually performed the control activity
I10: 세분화 수준 (비고: 보다 세분화/분산된 수준에서 수행되는 통제 활동이 상위 수준에서 수행되는 활동보다 더 정확함) Review control의 대상이 되는 정보를 고려하고, 이러한 정보가 효과적인 review control이 이루어질 수 있도록(즉, 중요한 왜곡표시를 적시에 식별하고 수정할 수 있도록) 충분히 세부적인 수준으로 제공되는지 여부를 평가한다. Describe the level of aggregation(Note: A control activity that is performed at a more granular/disaggregated level is more precise than one performed at a higher level) Include consideration of the information subject to the review control and address whether such information is provided at a sufficiently detailed level to allow for an effective review (i.e, timely identification and correction of material misstatements). | J10: 통제 활동의 빈도(예, 매분기, 매주), 정기적으로 혹은 비반복적으로 운영되는지 여부, 통제 활동의 수행에 사용되는 정보의 일관성, 통제 활동을 수행하는 인원의 일관성 및 통제 활동이 수행되는 방법의 일관성. Describe the frequency of the control activity (e.g., quarterly, weekly), whether it operates routinely or on a non-recurring basis, the consistency of the information used in the operation of the control activity, the consistency of the individuals who perform the control activity, and the consistency of the method by which the control activity is executed. | K10: Investigation을 수행하는 기준 (Investigation을 수행하는 기준이 되는 양적 threshold를 일관성있게 적용하고 있는가? 그러한 threshold가 존재하지 않는 경우, investigation이 필요한 사항을 결정하기 위해 일관성있게 적용되는 기준을 설명.) Describe the criteria for investigation (Is there a quantitative threshold at which investigation would consistently be performed? If not, describe the criteria used to determine matters that would be investigated consistently.) | L10: 예상치의 예측가능성 (통제활동의 효과성이 얼마나 정확한 예측치를 도출할 수 있는지 여부에 의존하는 경우, 계정의 성격 및 이용가능한 정보를 근거로 그러한 예측치가 얼마나 예측가능한지 고려.) Describe the predictability of expectations (If the effectiveness of the control activity depends on being able to develop sufficiently precise expectations, consider how predictable they can be based on the nature of the account and information available.)
A11: 1
A12: 2

Sheet Control Activity-1 - v2016
B1: Prior year control testing documentation rolled forward for reference purposes.
B2: 운영 효과성에 대한 테스트 - 통제 활동 1 Operating Effectiveness Testing - Control Activity-1
B3: Note: 각 통제 활동에 대하여 별도의 테스트 탭을 생성하여야 함 Note: A separate testing tab should be created for each control activity
B4: 동 review control activity와 관련된 LSPM은 무엇인가? (개별 통제 활동의 목적 및 설계에 대한 세부적인 이해에 근거하여 이 review control에 대한 설계 평가에 대한 결론을 내릴 때, 통제 활동이 관련 LSPM(Aura v6의 Risk Strategy view 및 설계 평가에 문서화된 바와 같이)에 대응하는지 재확인하여야 함) What LSPMs are relevant for this review control activity? (In finalizing the assessment of the design of this review control (based on a detailed understanding of the objective and design of individual control activities), we should reconfirm the control activity is responsive to the LSPMs to which is it linked (in the Risk Strategy view of Aura v6 and as documented in the design evaluation))
B5: 통제 활동의 내용 [어떻게 통제 운영자가 통제 활동의 목적을 달성하는지(즉, 통제 운영자가 정확하게 무엇을, 얼마나 정밀한 수준으로 수행하는지)?] Control Activity Description [How does the control operator accomplish the objective of this control activity (i.e., what exactly does the control operator do and at what level of precision)?]
B7: 1) 테스트 모집단을 결정 1) Determine the population(s) for testing | I7: 2) 통제 활동의 빈도 및 계획한 감사증거 수준에 따라 테스트할 기간의 개수 결정 2) Determine the number of periods to test based on the frequency of the control activity and the desired level of evidence
B8: 샘플을 선정하고 결론을 도출할 모집단을 식별 Note: 샘플을 선정하고 결론을 도출할 모집단은 사람, 프로세스, 연관 시스템, 공동의 ELC, 공동의 관리/감독, 공동의 실패 위험 등의 요소들을 고려하였을 때 하나의 모집단으로 테스트할 수 있을 만큼 충분히 동질적이어야 함. 추가적인 지침은 US PwC Audit 5400(US PwC Audit (NP) 5400)을 참조. Identify the population from which to select the sample and about which to draw conclusions Note: the population from which to select a sample and draw conclusions should be sufficiently homogenous to test as one population based on consideration of factors such as the people, processes, and systems involved, commonality of ELCs, commonality of supervisory oversight, common risks of failure, etc. Refer to US PwC Audit 5400 (US PwC Audit (NP) 5400) for further guidance. | I8: 통제 활동의 빈도 (예, 연간, 분기별, 월별, 주별, 일별, 1일 수시) Frequency of control activity (e.g., annual, quarterly, monthly, weekly, daily, multiple times per day)
B9: 모집단 완전성을 판단하기 위하여 수행한 절차 Procedures performed to determine the population is complete | I9: 통제 활동의 빈도 및 계획한 감사증거 수준에 따른 테스트 대상 기간 수(추가적인 지침은 US PwC Audit 5400 (US PwC Audit (NP) 5400)을 참조) Number of periods to test based on the frequency of the control activity and the desired level of evidence (Refer to US PwC Audit 5400 (US PwC Audit (NP) 5400) for further guidance)
B11: 3) 각 기간에 대하여 테스트할 통제 활동의 instance 개수 결정 3) Determine the number of instances of the control activity to test for each period | I11: 4a) 경영진이 사용한 정보가 의도된 목적(그러한 절차의 결과를 문서화하는 것을 포함하여) 상 신뢰성이 있는지(즉, 완전하고 정확한지) 확인하기 위해, 이 통제 활동의 운영에 중요하게 사용되는 정보에 대한 통제를 테스트 4a) Test the control(s) over information used in and important to the operation of this control activity used by management to ensure such information is reliable (i.e., is complete and accurate) for its intended purpose, including documenting the results of those procedures
B12: 각 모집단의 각 기간에 수행되는 통제 활동의 instance 개수 Note: 모집단 내에서 각 기간에 통제 활동이 1회를 초과하여 일어나는 경우, 통제 활동이 설계대로 일관성있게 운영되었음을 입증하기 위하여 필요한 감사증거의 범위를 결정하기 위하여 각 기간에 대하여 테스트할 통제 활동의 instance 개수를 결정함. 이러한 결정은 통제 활동과 연관된 위험, 이용가능한 감사증거 및 과거 경험에 근거한 전문가적 판단의 문제이다. 추가적인 지침은 US PwC Audit 5400 (US PwC Audit (NP) 5400)을 참조. Number of instances the control activity operates during each period for each population Note: In situations where a control activity occurs more than once per period within a population, determine the number of instances of the control activity to test for each period to determine the extent of evidence needed to be persuaded the control activity is operating consistently as designed. This determination is a matter of professional judgment and is based on the risk associated with the control activity, available evidence, and prior experience. Refer to US PwC Audit 5400 (US PwC Audit (NP) 5400) for further guidance. | I12: 통제 활동의 운영에 중요하게 사용되는 정보에 대하여, 그러한 정보의 신뢰성(즉, 완전하고 정확함)과 관련한 확신을 제공하기 위하여 경영진이 의존한 통제의 내용 For information determined to be used in and important to the operation of this control activity, describe the control(s) management is relying on to provide assurance regarding the reliability (i.e., it is complete and accurate) of such information. | L12: =IF('Master Control Design'!P12 = "", "", 'Master Control Design'!P12)
I13: 경영진의 통제 절차에 대한 통제 테스트의 결과를 기재하거나, 테스트 절차가 수행된 조서에 대한 링크를 첨부 Note: 통합감사의 경우, 이 통제 활동 운영에 사용된 정보의 신뢰성에 대한 우리의 독립적인 테스트와는 별개로 이러한 정보에 대한 경영진의 통제를 테스트하여야 함. Include the results of the control(s) testing over management's control procedures or reference to where the testing procedures are performed. Note: Our own independent testing over the reliability of the information used in the operation of this control activity would not substitute for our requirement to test management's controls over such information in an integrated audit.
B15: 4b) 선택한 통제 활동의 instance를 테스트 4b) Test the control activity instances selected
B16: 해당되는 모든 항목에 체크: Check all that apply:
A18: FALSE | B18: 질문 절차 - (질문만으로는 운영 효과성과 관련된 결론을 뒷받침하기에 충분하지 않음에 유의) Inquiry Procedures - (Reminder - inquiry alone is not sufficient to support conclusion regarding operating effectiveness)
B20: 테스트 계획 Test Plan | I20: 통제 활동에 investigation 기준이나 thresholds가 포함되는 경우, 테스트 계획에 확인할 후속조치의 개수에 대한 고려 뿐만 아니라 경영진이 통제 활동의 설계와 일관성있게 후속조치 및 investigation 항목을 모두 적절히 식별하였는지 여부를 판단하기 위한 절차가 포함되었는지 확인. 'Review' 통제 활동의 설계, 성격 및 빈도에 따라서, "Management Follow-up Items" 및 "Detailed Testing Table" 탭이 필요할 수 있음. In situations where the control activity includes criteria and/or thresholds for items being investigated, ensure the plan includes consideration for the number of follow-ups to corroborate as well as procedures to determine whether management appropriately identified all items for follow up and investigation consistent with the design of the control activity. The tabs “management Follow-up Items” and “Detailed Testing Table” may be needed based upon the design, nature and frequency of the ‘review’ control activity.
B21: 이 통제 활동과 관련된 질문 절차 수행 계획을 세부적으로 기재 (질문만으로는 운영 효과성과 관련된 결론을 뒷받침하기에 충분하지 않음에 유의) Describe in detail the plan to perform inquiry procedures related to this control activity (Reminder - inquiry alone is not sufficient to support conclusion regarding operating effectiveness)
B24: [대상기간 기재]에 대한 테스트 결과 Testing Results for [insert period] | I24: [대상기간 기재]에 대한 테스트 결과 Testing Results for [insert period]
A25: 1 | B25: 문서화 항목 Documentation Prompt | D25: 감사 증거 Evidence | G25: 예외사항 Exception(s) | I25: 문서화 항목 Documentation Prompt | K25: 감사 증거 Evidence | N25: 예외사항 Exception(s)
B26: 누구에게 질문이 수행되었는가? With whom were inquiries performed? | I26: 누구에게 질문이 수행되었는가? With whom were inquiries performed?
B27: 질문 수행 일자 Date inquiries were performed | I27: 질문 수행 일자 Date inquiries were performed
B28: 통제 활동 운영과 관련하여 통제 운영자에게 질문한 내용(보충 질문의 경우, 검토대상 업무의 수행자 또는 기타의 인원) Question asked of the control operator related to the operation of the control activity (or preparer or others if these are corroborative inquiries) | I28: 통제 활동 운영과 관련하여 통제 운영자에게 질문한 내용(보충 질문의 경우, 검토대상 업무의 수행자 또는 기타의 인원) Question asked of the control operator related to the operation of the control activity (or preparer or others if these are corroborative inquiries)
B29: 답변 Response provided | I29: 답변 Response provided
A32: FALSE | B32: 관찰 절차 Observation Procedures
B34: 테스트 계획 Test Plan | I34: 통제 활동에 investigation 기준이나 thresholds가 포함되는 경우, 테스트 계획에 확인할 후속조치의 개수에 대한 고려 뿐만 아니라 경영진이 통제 활동의 설계와 일관성있게 후속조치 및 investigation 항목을 모두 적절히 식별하였는지 여부를 판단하기 위한 절차가 포함되었는지 확인. 'Review' 통제 활동의 설계, 성격 및 빈도에 따라서, "Management Follow-up Items" 및 "Detailed Testing Table" 탭이 필요할 수 있음. In situations where the control activity includes criteria and/or thresholds for items being investigated, ensure the plan includes consideration for the number of follow-ups to corroborate as well as procedures to determine whether management appropriately identified all items for follow up and investigation consistent with the design of the control activity. The tabs “management Follow-up Items” and “Detailed Testing Table” may be needed based upon the design, nature and frequency of the ‘review’ control activity.
B35: 관찰 절차 수행 계획 및 입수할 감사증거의 세부 내역을 기재(각 기간의 테스트 항목 개수, 관련된 선정 기준 포함) Describe in detail the plan to perform observation procedures and the expected evidence to be obtained, including the number of items to be tested for each period and the related basis of selection
B38: [대상기간 기재]에 대한 테스트 결과 Testing Results for [insert period] | I38: [대상기간 기재]에 대한 테스트 결과 Testing Results for [insert period]
B39: 문서화 항목 Documentation Prompt | D39: 감사 증거 Evidence | G39: 예외사항 Exception(s) | I39: 문서화 항목 Documentation Prompt | K39: 감사 증거 Evidence | N39: 예외사항 Exception(s)
B40: 회의 또는 토론 일자 Meeting or discussion date | I40: 회의 또는 토론 일자 Meeting or discussion date
B41: 참석자 및 역할 (감사팀 및 기타 인원) Attendees and roles (Engagement team and others) | I41: 참석자 및 역할 (감사팀 및 기타 인원) Attendees and roles (Engagement team and others)
B42: 통제 운영자가 요청한 특정 조치 또는 통제운영자가 제기한 질문, 회의 또는 토론에서 논의된 사항들 Specific actions requested or questions raised by the control operator(s) and items discussed in the meeting or discussion | I42: 통제 운영자가 요청한 특정 조치 또는 통제운영자가 제기한 질문, 회의 또는 토론에서 논의된 사항들 Specific actions requested or questions raised by the control operator(s) and items discussed in the meeting or discussion
B43: 논의의 완전성에 대한 감사 증거(토론에서 다루어진 특정 내용이 설계평가 상 통제 활동의 정밀함의 수준을 뒷받침하는지의 여부를 포함) Evidence of completeness of the discussions, including whether specific matters addressed supported the designed precision level of the control activity | I43: 논의의 완전성에 대한 감사 증거(토론에서 다루어진 특정 내용이 설계평가 상 통제 활동의 정밀함의 수준을 뒷받침하는지의 여부를 포함) Evidence of completeness of the discussions, including whether specific matters addressed supported the designed precision level of the control activity
B44: Review의 정확성 및 효과성에 대한 증거를 제공하는, 토론의 결과로 도출된 후속조치 항목이나 변동 사항을 설명 Describe any follow-up items or changes resulting from the discussion that provide evidence of the precision and effectiveness of the review | I44: Review의 정확성 및 효과성에 대한 증거를 제공하는, 토론의 결과로 도출된 후속조치 항목이나 변동 사항을 설명 Describe any follow-up items or changes resulting from the discussion that provide evidence of the precision and effectiveness of the review
B45: 통제 운영자가 그에 필요한 지식 및 경험을 보여주는가? 그렇다면, 어떻게? Did the control operator demonstrate the requisite knowledge and experience? If so, how? | I45: 통제 운영자가 그에 필요한 지식 및 경험을 보여주는가? 그렇다면, 어떻게? Did the control operator demonstrate the requisite knowledge and experience? If so, how?
B46: 상기의 고려사항들이 전반적인 review의 범위 및 정확성에 관한 우리의 결론을 뒷받침하는가? 그렇다면, 어떻게? Did the considerations above support our conclusion regarding the overall scope and precision of the review? If so, how? | I46: 상기의 고려사항들이 전반적인 review의 범위 및 정확성에 관한 우리의 결론을 뒷받침하는가? 그렇다면, 어떻게? Did the considerations above support our conclusion regarding the overall scope and precision of the review? If so, how?
A48: FALSE | B48: 문서검사 절차 Inspection Procedures
B50: 테스트 계획 Test Plan | I50: 통제 활동에 investigation 기준이나 thresholds가 포함되는 경우, 테스트 계획에 확인할 후속조치의 개수에 대한 고려 뿐만 아니라 경영진이 통제 활동의 설계와 일관성있게 후속조치 및 investigation 항목을 모두 적절히 식별하였는지 여부를 판단하기 위한 절차가 포함되었는지 확인. 'Review' 통제 활동의 설계, 성격 및 빈도에 따라서, "Management Follow-up Items" 및 "Detailed Testing Table" 탭이 필요할 수 있음. In situations where the control activity includes criteria and/or thresholds for items being investigated, ensure the plan includes consideration for the number of follow-ups to corroborate as well as procedures to determine whether management appropriately identified all items for follow up and investigation consistent with the design of the control activity. The tabs “management Follow-up Items” and “Detailed Testing Table” may be needed based upon the design, nature and frequency of the ‘review’ control activity.
B51: 문서검사 절차 수행 계획 및 입수할 감사증거의 세부 내역을 기재(각 기간의 테스트 항목 개수, 관련된 선정 기준 포함) Describe in detail the plan to perform inspection procedures and the expected evidence to be obtained, including the number of items to be tested for each period and the related basis of selection
B54: [대상기간 기재]에 대한 테스트 결과 Testing Results for [insert period] | I54: [대상기간 기재]에 대한 테스트 결과 Testing Results for [insert period]
B55: 문서화 항목 Documentation Prompt | D55: 감사 증거 Evidence | G55: 예외사항 Exception(s) | I55: 문서화 항목 Documentation Prompt | K55: 감사 증거 Evidence | N55: 예외사항 Exception(s)
B56: 검사한 통제 활동 문서에 대한 감사 증거(해당 항목에 체크): (비고: 아래의 내역이 모두 포함되어야 하거나, 나열된 항목이 모두 요구되는 것은 아님. 추가적인 지침은 PwC Audit 4165.12를 참조.) Evidence of control activity documentation inspected (check those that apply): (Note: the list below is not all-inclusive and not all items listed below are required. Refer to PwC Audit 4165.12 for further guidance.) | I56: 검사한 통제 활동 문서에 대한 감사 증거(해당 항목에 체크): (비고: 아래의 내역이 모두 포함되어야 하거나, 나열된 항목이 모두 요구되는 것은 아님. 추가적인 지침은 PwC Audit 4165.12를 참조.) Evidence of control activity documentation inspected (check those that apply): (Note: the list below is not all-inclusive and not all items listed below are required. Refer to PwC Audit 4165.12 for further guidance.)
...

Sheet Control Activity-2 - v2016
B1: Prior year control testing documentation rolled forward for reference purposes.
B2: 운영효과성에 대한 테스트 - 통제활동 2 Operating Effectiveness Testing - Control Activity-2
B3: Note: 각 통제 활동에 대하여 별도의 테스트 탭을 생성하여야 함 Note: A separate testing tab should be created for each control activity
B4: 동 review control activity와 관련된 LSPM은 무엇인가? (개별 통제 활동의 목적 및 설계에 대한 세부적인 이해에 근거하여 이 review control에 대한 설계 평가에 대한 결론을 내릴 때, 통제 활동이 관련 LSPM(Aura v6의 Risk Strategy view 및 설계 평가에 문서화된 바와 같이)에 대응하는지 재확인하여야 함) What LSPMs are relevant for this review control activity? (In finalizing the assessment of the design of this review control (based on a detailed understanding of the objective and design of individual control activities), we should reconfirm the control activity is responsive to the LSPMs to which is it linked (in the Risk Strategy view of Aura v6 and as documented in the design evaluation))
B5: 통제 활동의 내용 [어떻게 통제 운영자가 통제 활동의 목적을 달성하는지(즉, 통제 운영자가 정확하게 무엇을, 얼마나 정밀한 수준으로 수행하는지)?] Control Activity Description [How does the control operator accomplish the objective of this control activity (i.e., what exactly does the control operator do and at what level of precision)?]
B7: 1) 테스트 모집단을 결정 1) Determine the population(s) for testing | I7: 2) 통제 활동의 빈도 및 계획한 감사증거 수준에 따라 테스트할 기간의 개수 결정 2) Determine the number of periods to test based on the frequency of the control activity and the desired level of evidence
B8: 샘플을 선정하고 결론을 도출할 모집단을 식별 Note: 샘플을 선정하고 결론을 도출할 모집단은 사람, 프로세스, 연관 시스템, 공동의 ELC, 공동의 관리/감독, 공동의 실패 위험 등의 요소들을 고려하였을 때 하나의 모집단으로 테스트할 수 있을 만큼 충분히 동질적이어야 함. 추가적인 지침은 US PwC Audit 5400(US PwC Audit (NP) 5400)을 참조. Identify the population from which to select the sample and about which to draw conclusions Note: the population from which to select a sample and draw conclusions should be sufficiently homogenous to test as one population based on consideration of factors such as the people, processes, and systems involved, commonality of ELCs, commonality of supervisory oversight, common risks of failure, etc. Refer to US PwC Audit 5400 (US PwC Audit (NP) 5400) for further guidance. | I8: 통제 활동의 빈도 (예, 연간, 분기별, 월별, 주별, 일별, 1일 수시) Frequency of control activity (e.g., annual, quarterly, monthly, weekly, daily, multiple times per day)
B9: 모집단 완전성을 판단하기 위하여 수행한 절차 Procedures performed to determine the population is complete | I9: 통제 활동의 빈도 및 계획한 감사증거 수준에 따른 테스트 대상 기간 수(추가적인 지침은 US PwC Audit 5400 (US PwC Audit (NP) 5400)을 참조) Number of periods to test based on the frequency of the control activity and the desired level of evidence (Refer to US PwC Audit 5400 (US PwC Audit (NP) 5400) for further guidance)
B11: 3) 각 기간에 대하여 테스트할 통제 활동의 instance 개수 결정 3) Determine the number of instances of the control activity to test for each period | I11: 4a) 경영진이 사용한 정보가 의도된 목적(그러한 절차의 결과를 문서화하는 것을 포함하여) 상 신뢰성이 있는지(즉, 완전하고 정확한지) 확인하기 위해, 이 통제 활동의 운영에 중요하게 사용되는 정보에 대한 통제를 테스트 4a) Test the control(s) over information used in and important to the operation of this control activity used by management to ensure such information is reliable (i.e., is complete and accurate) for its intended purpose, including documenting the results of those procedures
B12: 각 모집단의 각 기간에 수행되는 통제 활동의 instance 개수 Note: 모집단 내에서 각 기간에 통제 활동이 1회를 초과하여 일어나는 경우, 통제 활동이 설계대로 일관성있게 운영되었음을 입증하기 위하여 필요한 감사증거의 범위를 결정하기 위하여 각 기간에 대하여 테스트할 통제 활동의 instance 개수를 결정함. 이러한 결정은 통제 활동과 연관된 위험, 이용가능한 감사증거 및 과거 경험에 근거한 전문가적 판단의 문제이다. 추가적인 지침은 US PwC Audit 5400 (US PwC Audit (NP) 5400)을 참조. Number of instances the control activity operates during each period for each population Note: In situations where a control activity occurs more than once per period within a population, determine the number of instances of the control activity to test for each period to determine the extent of evidence needed to be persuaded the control activity is operating consistently as designed. This determination is a matter of professional judgment and is based on the risk associated with the control activity, available evidence, and prior experience. Refer to US PwC Audit 5400 (US PwC Audit (NP) 5400) for further guidance. | I12: 통제 활동의 운영에 중요하게 사용되는 정보에 대하여, 그러한 정보의 신뢰성(즉, 완전하고 정확함)과 관련한 확신을 제공하기 위하여 경영진이 의존한 통제의 내용 For information determined to be used in and important to the operation of this control activity, describe the control(s) management is relying on to provide assurance regarding the reliability (i.e., it is complete and accurate) of such information. | L12: =IF('Master Control Design'!P12 = "", "", 'Master Control Design'!P12)
I13: 경영진의 통제 절차에 대한 통제 테스트의 결과를 기재하거나, 테스트 절차가 수행된 조서에 대한 링크를 첨부 Note: 통합감사의 경우, 이 통제 활동 운영에 사용된 정보의 신뢰성에 대한 우리의 독립적인 테스트와는 별개로 이러한 정보에 대한 경영진의 통제를 테스트하여야 함. Include the results of the control(s) testing over management's control procedures or reference to where the testing procedures are performed. Note: Our own independent testing over the reliability of the information used in the operation of this control activity would not substitute for our requirement to test management's controls over such information in an integrated audit.
B15: 4b) 선택한 통제 활동의 instance를 테스트 4b) Test the control activity instances selected
B16: 해당되는 모든 항목에 체크: Check all that apply:
A18: FALSE | B18: 질문 절차 - (질문만으로는 운영 효과성과 관련된 결론을 뒷받침하기에 충분하지 않음에 유의) Inquiry Procedures - (Reminder - inquiry alone is not sufficient to support conclusion regarding operating effectiveness)
B20: 테스트 계획 Test Plan | I20: 통제 활동이 조사될 항목에 대한 기준/threshold을 포함하고 있는 경우, 동 계획이 확증을 위한 후속조치의 건수뿐만 아니라 경영진이 통제 활동 설계와 일치하는 후속조치 및 조사를 위한 모든 항목을 적절하게 식별했는지의 여부를 결정하는 절차에 대한 고려를 포함하여야 한다. 'Review' 통제 활동의 설계, 성격 및 빈도에 따라 "Management Follow-up Items" 및 "Detailed Testing Table" 탭이 필요할 수 있다. In situations where the control activity includes criteria and/or thresholds for items being investigated, ensure the plan includes consideration for the number of follow-ups to corroborate as well as procedures to determine whether management appropriately identified all items for follow up and investigation consistent with the design of the control activity. The tabs “management Follow-up Items” and “Detailed Testing Table” may be needed based upon the design, nature and frequency of the ‘review’ control activity.
B21: 이 통제 활동과 관련된 질문 절차 수행 계획을 세부적으로 기재 (질문만으로는 운영 효과성과 관련된 결론을 뒷받침하기에 충분하지 않음에 유의) Describe in detail the plan to perform inquiry procedures related to this control activity (Reminder - inquiry alone is not sufficient to support conclusion regarding operating effectiveness)
B24: [대상기간 기재]에 대한 테스트 결과 Testing Results for [insert period] | I24: [대상기간 기재]에 대한 테스트 결과 Testing Results for [insert period]
A25: 1 | B25: 문서화 항목 Documentation Prompt | D25: 감사 증거 Evidence | G25: 예외사항 Exception(s) | I25: 문서화 항목 Documentation Prompt | K25: 감사 증거 Evidence | N25: 예외사항 Exception(s)
B26: 누구에게 질문이 수행되었는가? With whom were inquiries performed? | I26: 누구에게 질문이 수행되었는가? With whom were inquiries performed?
B27: 질문 수행 일자 Date inquiries were performed | I27: 질문 수행 일자 Date inquiries were performed
B28: 통제 활동 운영과 관련하여 통제 운영자에게 질문한 내용(보충 질문의 경우, 검토대상 업무의 수행자 또는 기타의 인원) Question asked of the control operator related to the operation of the control activity (or preparer or others if these are corroborative inquiries) | I28: 통제 활동 운영과 관련하여 통제 운영자에게 질문한 내용(보충 질문의 경우, 검토대상 업무의 수행자 또는 기타의 인원) Question asked of the control operator related to the operation of the control activity (or preparer or others if these are corroborative inquiries)
B29: 답변 Response provided | I29: 답변 Response provided
A32: FALSE | B32: 관찰 절차 Observation Procedures
B34: 테스트 계획 Test Plan | I34: 통제 활동에 investigation 기준이나 thresholds가 포함되는 경우, 테스트 계획에 확인할 후속조치의 개수에 대한 고려 뿐만 아니라 경영진이 통제 활동의 설계와 일관성있게 후속조치 및 investigation 항목을 모두 적절히 식별하였는지 여부를 판단하기 위한 절차가 포함되었는지 확인. 'Review' 통제 활동의 설계, 성격 및 빈도에 따라서, "Management Follow-up Items" 및 "Detailed Testing Table" 탭이 필요할 수 있음. In situations where the control activity includes criteria and/or thresholds for items being investigated, ensure the plan includes consideration for the number of follow-ups to corroborate as well as procedures to determine whether management appropriately identified all items for follow up and investigation consistent with the design of the control activity. The tabs “management Follow-up Items” and “Detailed Testing Table” may be needed based upon the design, nature and frequency of the ‘review’ control activity.
B35: 관찰 절차 수행 계획 및 입수할 감사증거의 세부 내역을 기재(각 기간의 테스트 항목 개수, 관련된 선정 기준 포함) Describe in detail the plan to perform observation procedures and the expected evidence to be obtained, including the number of items to be tested for each period and the related basis of selection
B38: [대상기간 기재]에 대한 테스트 결과 Testing Results for [insert period] | I38: [대상기간 기재]에 대한 테스트 결과 Testing Results for [insert period]
B39: 문서화 항목 Documentation Prompt | D39: 감사 증거 Evidence | G39: 예외사항 Exception(s) | I39: 문서화 항목 Documentation Prompt | K39: 감사 증거 Evidence | N39: 예외사항 Exception(s)
B40: 회의 또는 토론 일자 Meeting or discussion date | I40: 회의 또는 토론 일자 Meeting or discussion date
B41: 참석자 및 역할 (감사팀 및 기타 인원) Attendees and roles (Engagement team and others) | I41: 참석자 및 역할 (감사팀 및 기타 인원) Attendees and roles (Engagement team and others)
B42: 통제 운영자가 요구한 특정 행동이나 제기한 질문 및 회의나 토론에서 다루어진 항목 Specific actions requested or questions raised by the control operator(s) and items discussed in the meeting or discussion | I42: 통제 운영자가 요구한 특정 행동이나 제기한 질문 및 회의나 토론에서 다루어진 항목 Specific actions requested or questions raised by the control operator(s) and items discussed in the meeting or discussion
B43: 토론에서 다루어진 특정 사항이 통제 활동의 계획된 정확도 수준을 뒷받침하는지의 여부 등과 같이 토론의 완전성에 대한 증거 Evidence of completeness of the discussions, including whether specific matters addressed supported the designed precision level of the control activity | I43: 토론에서 다루어진 특정 사항이 통제 활동의 계획된 정확도 수준을 뒷받침하는지의 여부 등과 같이 토론의 완전성에 대한 증거 Evidence of completeness of the discussions, including whether specific matters addressed supported the designed precision level of the control activity
B44: 검토의 정확성 및 효과성에 대한 증거를 제시한 토론에서 나온 후속조치 항목이나 변동사항을 설명한다 Describe any follow-up items or changes resulting from the discussion that provide evidence of the precision and effectiveness of the review | I44: 검토의 정확성 및 효과성에 대한 증거를 제시한 토론에서 나온 후속조치 항목이나 변동사항을 설명한다 Describe any follow-up items or changes resulting from the discussion that provide evidence of the precision and effectiveness of the review
B45: 통제 운영자가 필수 지식 및 경험을 발휘하였는가? 그렇다면, 어떻게 발휘하였는가? Did the control operator demonstrate the requisite knowledge and experience? If so, how? | I45: 통제 운영자가 필수 지식 및 경험을 발휘하였는가? 그렇다면, 어떻게 발휘하였는가? Did the control operator demonstrate the requisite knowledge and experience? If so, how?
B46: 상기의 고려사항들이 검토의 전반적인 범위 및 정확성에 관한 우리의 결론을 뒷받침해주는가? 그렇다면, 어떻게 뒷받침해주는가? Did the considerations above support our conclusion regarding the overall scope and precision of the review? If so, how? | I46: 상기의 고려사항들이 검토의 전반적인 범위 및 정확성에 관한 우리의 결론을 뒷받침해주는가? 그렇다면, 어떻게 뒷받침해주는가? Did the considerations above support our conclusion regarding the overall scope and precision of the review? If so, how?
A48: FALSE | B48: 문서검사 절차 Inspection Procedures
B50: 테스트 계획 Test Plan | I50: 통제 활동에 investigation 기준이나 thresholds가 포함되는 경우, 테스트 계획에 확인할 후속조치의 개수에 대한 고려 뿐만 아니라 경영진이 통제 활동의 설계와 일관성있게 후속조치 및 investigation 항목을 모두 적절히 식별하였는지 여부를 판단하기 위한 절차가 포함되었는지 확인. 'Review' 통제 활동의 설계, 성격 및 빈도에 따라서, "Management Follow-up Items" 및 "Detailed Testing Table" 탭이 필요할 수 있음. In situations where the control activity includes criteria and/or thresholds for items being investigated, ensure the plan includes consideration for the number of follow-ups to corroborate as well as procedures to determine whether management appropriately identified all items for follow up and investigation consistent with the design of the control activity. The tabs “management Follow-up Items” and “Detailed Testing Table” may be needed based upon the design, nature and frequency of the ‘review’ control activity.
B51: 문서검사 절차 수행 계획 및 입수할 감사증거의 세부 내역을 기재(각 기간의 테스트 항목 개수, 관련된 선정 기준 포함) Describe in detail the plan to perform inspection procedures and the expected evidence to be obtained, including the number of items to be tested for each period and the related basis of selection
B54: [대상기간 기재]에 대한 테스트 결과 Testing Results for [insert period] | I54: [대상기간 기재]에 대한 테스트 결과 Testing Results for [insert period]
B55: 문서화 항목 Documentation Prompt | D55: 감사 증거 Evidence | G55: 예외사항 Exception(s) | I55: 문서화 항목 Documentation Prompt | K55: 감사 증거 Evidence | N55: 예외사항 Exception(s)
B56: 검사한 통제 활동 문서에 대한 감사 증거(해당 항목에 체크): (비고: 아래의 내역이 모두 포함되어야 하거나, 나열된 항목이 모두 요구되는 것은 아님. 추가적인 지침은 PwC Audit 4165.12를 참조.) Evidence of control activity documentation inspected (check those that apply): (Note: the list below is not all-inclusive and not all items listed below are required. Refer to PwC Audit 4165.12 for further guidance.) | I56: 검사한 통제 활동 문서에 대한 감사 증거(해당 항목에 체크): (비고: 아래의 내역이 모두 포함되어야 하거나, 나열된 항목이 모두 요구되는 것은 아님. 추가적인 지침은 PwC Audit 4165.12를 참조.) Evidence of control activity documentation inspected (check those that apply): (Note: the list below is not all-inclusive and not all items listed below are required. Refer to PwC Audit 4165.12 for further guidance.)
...

Sheet Master Control Activity v2016
B1: Prior year control testing documentation rolled forward for reference purposes.
B2: 운영효과성에 대한 테스트 - 통제활동- Operating Effectiveness Testing - Control Activity-
B3: Note: 각 통제 활동에 대하여 별도의 테스트 탭을 생성하여야 함 Note: A separate testing tab should be created for each control activity
B4: 동 review control activity와 관련된 LSPM은 무엇인가? (개별 통제 활동의 목적 및 설계에 대한 세부적인 이해에 근거하여 이 review control에 대한 설계 평가에 대한 결론을 내릴 때, 통제 활동이 관련 LSPM(Aura v6의 Risk Strategy view 및 설계 평가에 문서화된 바와 같이)에 대응하는지 재확인하여야 함) What LSPMs are relevant for this review control activity? (In finalizing the assessment of the design of this review control (based on a detailed understanding of the objective and design of individual control activities), we should reconfirm the control activity is responsive to the LSPMs to which is it linked (in the Risk Strategy view of Aura v6 and as documented in the design evaluation))
B5: 통제 활동의 내용 [어떻게 통제 운영자가 통제 활동의 목적을 달성하는지(즉, 통제 운영자가 정확하게 무엇을, 얼마나 정밀한 수준으로 수행하는지)?] Control Activity Description [How does the control operator accomplish the objective of this control activity (i.e., what exactly does the control operator do and at what level of precision)?]
B7: 1) 테스트 모집단을 결정 1) Determine the population(s) for testing | I7: 2) 통제 활동의 빈도 및 계획한 감사증거 수준에 따라 테스트할 기간의 개수 결정 2) Determine the number of periods to test based on the frequency of the control activity and the desired level of evidence
B8: 샘플을 선정하고 결론을 도출할 모집단을 식별 Note: 샘플을 선정하고 결론을 도출할 모집단은 사람, 프로세스, 연관 시스템, 공동의 ELC, 공동의 관리/감독, 공동의 실패 위험 등의 요소들을 고려하였을 때 하나의 모집단으로 테스트할 수 있을 만큼 충분히 동질적이어야 함. 추가적인 지침은 US PwC Audit 5400(US PwC Audit (NP) 5400)을 참조. Identify the population from which to select the sample and about which to draw conclusions Note: the population from which to select a sample and draw conclusions should be sufficiently homogenous to test as one population based on consideration of factors such as the people, processes, and systems involved, commonality of ELCs, commonality of supervisory oversight, common risks of failure, etc. Refer to US PwC Audit 5400 (US PwC Audit (NP) 5400) for further guidance. | I8: 통제 활동의 빈도 (예, 연간, 분기별, 월별, 주별, 일별, 1일 수시) Frequency of control activity (e.g., annual, quarterly, monthly, weekly, daily, multiple times per day)
B9: 모집단 완전성을 판단하기 위하여 수행한 절차 Procedures performed to determine the population is complete | I9: 통제 활동의 빈도 및 계획한 감사증거 수준에 따른 테스트 대상 기간 수(추가적인 지침은 US PwC Audit 5400 (US PwC Audit (NP) 5400)을 참조) Number of periods to test based on the frequency of the control activity and the desired level of evidence (Refer to US PwC Audit 5400 (US PwC Audit (NP) 5400) for further guidance)
B11: 3) 각 기간에 대하여 테스트할 통제 활동의 instance 개수 결정 3) Determine the number of instances of the control activity to test for each period | I11: 4a) 경영진이 사용한 정보가 의도된 목적(그러한 절차의 결과를 문서화하는 것을 포함하여) 상 신뢰성이 있는지(즉, 완전하고 정확한지) 확인하기 위해, 이 통제 활동의 운영에 중요하게 사용되는 정보에 대한 통제를 테스트 4a) Test the control(s) over information used in and important to the operation of this control activity used by management to ensure such information is reliable (i.e., is complete and accurate) for its intended purpose, including documenting the results of those procedures
B12: 각 모집단의 각 기간에 수행되는 통제 활동의 instance 개수 Note: 모집단 내에서 각 기간에 통제 활동이 1회를 초과하여 일어나는 경우, 통제 활동이 설계대로 일관성있게 운영되었음을 입증하기 위하여 필요한 감사증거의 범위를 결정하기 위하여 각 기간에 대하여 테스트할 통제 활동의 instance 개수를 결정함. 이러한 결정은 통제 활동과 연관된 위험, 이용가능한 감사증거 및 과거 경험에 근거한 전문가적 판단의 문제이다. 추가적인 지침은 US PwC Audit 5400 (US PwC Audit (NP) 5400)을 참조. Number of instances the control activity operates during each period for each population Note: In situations where a control activity occurs more than once per period within a population, determine the number of instances of the control activity to test for each period to determine the extent of evidence needed to be persuaded the control activity is operating consistently as designed. This determination is a matter of professional judgment and is based on the risk associated with the control activity, available evidence, and prior experience. Refer to US PwC Audit 5400 (US PwC Audit (NP) 5400) for further guidance. | I12: 통제 활동의 운영에 중요하게 사용되는 정보에 대하여, 그러한 정보의 신뢰성(즉, 완전하고 정확함)과 관련한 확신을 제공하기 위하여 경영진이 의존한 통제의 내용 For information determined to be used in and important to the operation of this control activity, describe the control(s) management is relying on to provide assurance regarding the reliability (i.e., it is complete and accurate) of such information.
I13: 경영진의 통제 절차에 대한 통제 테스트의 결과를 기재하거나, 테스트 절차가 수행된 조서에 대한 링크를 첨부 Note: 통합감사의 경우, 이 통제 활동 운영에 사용된 정보의 신뢰성에 대한 우리의 독립적인 테스트와는 별개로 이러한 정보에 대한 경영진의 통제를 테스트하여야 함. Include the results of the control(s) testing over management's control procedures or reference to where the testing procedures are performed. Note: Our own independent testing over the reliability of the information used in the operation of this control activity would not substitute for our requirement to test management's controls over such information in an integrated audit.
B15: 4b) 선택한 통제 활동의 instance를 테스트 4b) Test the control activity instances selected
B16: 해당되는 모든 항목에 체크: Check all that apply:
A18: FALSE | B18: 질문 절차 - (질문만으로는 운영 효과성과 관련된 결론을 뒷받침하기에 충분하지 않음에 유의) Inquiry Procedures - (Reminder - inquiry alone is not sufficient to support conclusion regarding operating effectiveness)
B20: 테스트 계획 Test Plan | I20: 통제 활동에 investigation 기준이나 thresholds가 포함되는 경우, 테스트 계획에 확인할 후속조치의 개수에 대한 고려 뿐만 아니라 경영진이 통제 활동의 설계와 일관성있게 후속조치 및 investigation 항목을 모두 적절히 식별하였는지 여부를 판단하기 위한 절차가 포함되었는지 확인. 'Review' 통제 활동의 설계, 성격 및 빈도에 따라서, "Management Follow-up Items" 및 "Detailed Testing Table" 탭이 필요할 수 있음. In situations where the control activity includes criteria and/or thresholds for items being investigated, ensure the plan includes consideration for the number of follow-ups to corroborate as well as procedures to determine whether management appropriately identified all items for follow up and investigation consistent with the design of the control activity. The tabs “management Follow-up Items” and “Detailed Testing Table” may be needed based upon the design, nature and frequency of the ‘review’ control activity.
B21: 이 통제 활동과 관련된 질문 절차 수행 계획을 세부적으로 기재 (질문만으로는 운영 효과성과 관련된 결론을 뒷받침하기에 충분하지 않음에 유의) Describe in detail the plan to perform inquiry procedures related to this control activity (Reminder - inquiry alone is not sufficient to support conclusion regarding operating effectiveness)
B24: [대상기간 기재]에 대한 테스트 결과 Testing Results for [insert period] | I24: [대상기간 기재]에 대한 테스트 결과 Testing Results for [insert period]
A25: 1 | B25: 문서화 항목 Documentation Prompt | D25: 감사 증거 Evidence | G25: 예외사항 Exception(s) | I25: 문서화 항목 Documentation Prompt | K25: 감사 증거 Evidence | N25: 예외사항 Exception(s)
B26: 누구에게 질문이 수행되었는가? With whom were inquiries performed? | I26: 누구에게 질문이 수행되었는가? With whom were inquiries performed?
B27: 질문 수행 일자 Date inquiries were performed | I27: 질문 수행 일자 Date inquiries were performed
B28: 통제 활동 운영과 관련하여 통제 운영자에게 질문한 내용(보충 질문의 경우, 검토대상 업무의 수행자 또는 기타의 인원) Question asked of the control operator related to the operation of the control activity (or preparer or others if these are corroborative inquiries) | I28: 통제 활동 운영과 관련하여 통제 운영자에게 질문한 내용(보충 질문의 경우, 검토대상 업무의 수행자 또는 기타의 인원) Question asked of the control operator related to the operation of the control activity (or preparer or others if these are corroborative inquiries)
B29: 답변 Response provided | I29: 답변 Response provided
A32: FALSE | B32: 관찰 절차 Observation Procedures
B34: 테스트 계획 Test Plan | I34: 통제 활동에 investigation 기준이나 thresholds가 포함되는 경우, 테스트 계획에 확인할 후속조치의 개수에 대한 고려 뿐만 아니라 경영진이 통제 활동의 설계와 일관성있게 후속조치 및 investigation 항목을 모두 적절히 식별하였는지 여부를 판단하기 위한 절차가 포함되었는지 확인. 'Review' 통제 활동의 설계, 성격 및 빈도에 따라서, "Management Follow-up Items" 및 "Detailed Testing Table" 탭이 필요할 수 있음. In situations where the control activity includes criteria and/or thresholds for items being investigated, ensure the plan includes consideration for the number of follow-ups to corroborate as well as procedures to determine whether management appropriately identified all items for follow up and investigation consistent with the design of the control activity. The tabs “management Follow-up Items” and “Detailed Testing Table” may be needed based upon the design, nature and frequency of the ‘review’ control activity.
B35: 관찰 절차 수행 계획 및 입수할 감사증거의 세부 내역을 기재(각 기간의 테스트 항목 개수, 관련된 선정 기준 포함) Describe in detail the plan to perform observation procedures and the expected evidence to be obtained, including the number of items to be tested for each period and the related basis of selection
B38: [대상기간 기재]에 대한 테스트 결과 Testing Results for [insert period] | I38: [대상기간 기재]에 대한 테스트 결과 Testing Results for [insert period]
B39: 문서화 항목 Documentation Prompt | D39: 감사 증거 Evidence | G39: 예외사항 Exception(s) | I39: 문서화 항목 Documentation Prompt | K39: 감사 증거 Evidence | N39: 예외사항 Exception(s)
B40: 회의 또는 토론 일자 Meeting or discussion date | I40: 회의 또는 토론 일자 Meeting or discussion date
B41: 참석자 및 역할 (감사팀 및 기타 인원) Attendees and roles (Engagement team and others) | I41: 참석자 및 역할 (감사팀 및 기타 인원) Attendees and roles (Engagement team and others)
B42: 통제 운영자가 요청한 특정 조치 또는 통제운영자가 제기한 질문, 회의 또는 토론에서 논의된 사항들 Specific actions requested or questions raised by the control operator(s) and items discussed in the meeting or discussion | I42: 통제 운영자가 요청한 특정 조치 또는 통제운영자가 제기한 질문, 회의 또는 토론에서 논의된 사항들 Specific actions requested or questions raised by the control operator(s) and items discussed in the meeting or discussion
B43: 논의의 완전성에 대한 감사 증거(토론에서 다루어진 특정 내용이 설계평가 상 통제 활동의 정밀함의 수준을 뒷받침하는지의 여부를 포함) Evidence of completeness of the discussions, including whether specific matters addressed supported the designed precision level of the control activity | I43: 논의의 완전성에 대한 감사 증거(토론에서 다루어진 특정 내용이 설계평가 상 통제 활동의 정밀함의 수준을 뒷받침하는지의 여부를 포함) Evidence of completeness of the discussions, including whether specific matters addressed supported the designed precision level of the control activity
B44: Review의 정확성 및 효과성에 대한 증거를 제공하는, 토론의 결과로 도출된 후속조치 항목이나 변동 사항을 설명 Describe any follow-up items or changes resulting from the discussion that provide evidence of the precision and effectiveness of the review | I44: Review의 정확성 및 효과성에 대한 증거를 제공하는, 토론의 결과로 도출된 후속조치 항목이나 변동 사항을 설명 Describe any follow-up items or changes resulting from the discussion that provide evidence of the precision and effectiveness of the review
